Workbook

Sheet Tabela
A1: Cód. | B1: Município | C1: 2002 | D1: 2003 | E1: 2004 | F1: 2005 | G1: 2006 | H1: 2007 | I1: 2008 | J1: 2009 | K1: 2010 | L1: 2011 | M1: 2012 | N1: 2013 | O1: 2014 | P1: 2015 | Q1: 2016 | R1: 2017 | S1: 2018 | T1: 2019 | U1: 2020 | V1: 2021
A2: 1100015 | B2: Alta Floresta D'Oeste (RO) | C2: 27237 | D2: 27563 | E2: 29001 | F2: 28629 | G2: 29005 | H2: =(I2+G2)/2 -> 26791 | I2: 24577 | J2: 24354 | K2: =(L2+J2)/2 -> 24291 | L2: 24228 | M2: 24069 | N2: 25728 | O2: 25652 | P2: 25578 | Q2: 25506 | R2: 25437 | S2: 23167 | T2: 22945 | U2: 22728 | V2: 22516
A3: 1100023 | B3: Ariquemes (RO) | C3: 78039 | D3: 79680 | E3: 86901 | F3: 85031 | G3: 86924 | H3: =(I3+G3)/2 -> 85752.5 | I3: 84581 | J3: 85541 | K3: =(L3+J3)/2 -> 88555.5 | L3: 91570 | M3: 92747 | N3: 101269 | O3: 102860 | P3: 104401 | Q3: 105896 | R3: 107345 | S3: 106168 | T3: 107863 | U3: 109523 | V3: 111148
A4: 1100031 | B4: Cabixi (RO) | C4: 7490 | D4: 7478 | E4: 7421 | F4: 7436 | G4: 7421 | H4: =(I4+G4)/2 -> 7099 | I4: 6777 | J4: 6695 | K4: =(L4+J4)/2 -> 6458 | L4: 6221 | M4: 6132 | N4: 6495 | O4: 6424 | P4: 6355 | Q4: 6289 | R4: 6224 | S4: 5438 | T4: 5312 | U4: 5188 | V4: 5067
A5: 1100049 | B5: Cacoal (RO) | C5: 74381 | D5: 74758 | E5: 76417 | F5: 75988 | G5: 76422 | H5: =(I5+G5)/2 -> 77342.5 | I5: 78263 | J5: 78675 | K5: =(L5+J5)/2 -> 78817 | L5: 78959 | M5: 79330 | N5: 85863 | O5: 86556 | P5: 87226 | Q5: 87877 | R5: 88507 | S5: 84813 | T5: 85359 | U5: 85893 | V5: 86416
A6: 1100056 | B6: Cerejeiras (RO) | C6: 17925 | D6: 17794 | E6: 17217 | F6: 17366 | G6: 17215 | H6: =(I6+G6)/2 -> 16999.5 | I6: 16784 | J6: 16622 | K6: =(L6+J6)/2 -> 16780.5 | L6: 16939 | M6: 16852 | N6: 18041 | O6: 18013 | P6: 17986 | Q6: 17959 | R6: 17934 | S6: 16444 | T6: 16323 | U6: 16204 | V6: 16088
A7: 1100064 | B7: Colorado do Oeste (RO) | C7: 20881 | D7: 20412 | E7: 18349 | F7: 18883 | G7: 18342 | H7: =(I7+G7)/2 -> 18279 | I7: 18216 | J7: 17822 | K7: =(L7+J7)/2 -> 18080 | L7: 18338 | M7: 18093 | N7: 19190 | O7: 19001 | P7: 18817 | Q7: 18639 | R7: 18467 | S7: 16227 | T7: 15882 | U7: 15544 | V7: 15213
A8: 1100072 | B8: Corumbiara (RO) | C8: 10160 | D8: 10022 | E8: 9411 | F8: 9569 | G8: 9409 | H8: =(I8+G8)/2 -> 9585 | I8: 9761 | J8: 9680 | K8: =(L8+J8)/2 -> 9167.5 | L8: 8655 | M8: 8530 | N8: 9036 | O8: 8938 | P8: 8842 | Q8: 8749 | R8: 8659 | S8: 7567 | T8: 7391 | U8: 7220 | V8: 7052
A9: 1100080 | B9: Costa Marques (RO) | C9: 9919 | D9: 10255 | E9: 11731 | F9: 11349 | G9: 11735 | H9: =(I9+G9)/2 -> 12854 | I9: 13973 | J9: 14452 | K9: =(L9+J9)/2 -> 14237.5 | L9: 14023 | M9: 14355 | N9: 15853 | O9: 16258 | P9: 16651 | Q9: 17031 | R9: 17400 | S9: 17855 | T9: 18331 | U9: 18798 | V9: 19255
A10: 1100098 | B10: Espigão D'Oeste (RO) | C10: 26221 | D10: 26468 | E10: 27556 | F10: 27274 | G10: 27559 | H10: =(I10+G10)/2 -> 28088 | I10: 28617 | J10: 28892 | K10: =(L10+J10)/2 -> 28927.5 | L10: 28963 | M10: 29189 | N10: 31699 | O10: 32047 | P10: 32385 | Q10: 32712 | R10: 33030 | S10: 32047 | T10: 32374 | U10: 32695 | V10: 33009
A11: 1100106 | B11: Guajará-Mirim (RO) | C11: 39194 | D11: 39728 | E11: 42075 | F11: 41467 | G11: 42082 | H11: =(I11+G11)/2 -> 41311.5 | I11: 40541 | J11: 40762 | K11: =(L11+J11)/2 -> 41348 | L11: 41934 | M11: 42202 | N11: 45761 | O11: 46203 | P11: 46632 | Q11: 47048 | R11: 47451 | S11: 45783 | T11: 46174 | U11: 46556 | V11: 46930
A12: 1100114 | B12: Jaru (RO) | C12: 54352 | D12: 54701 | E12: 56238 | F12: 55840 | G12: 56242 | H12: =(I12+G12)/2 -> 55098.5 | I12: 53955 | J12: 53943 | K12: =(L12+J12)/2 -> 52913 | L12: 51883 | M12: 51765 | N12: 55597 | O12: 55669 | P12: 55738 | Q12: 55806 | R12: 55871 | S12: 51933 | T12: 51775 | U12: 51620 | V12: 51469
A13: 1100122 | B13: Ji-Paraná (RO) | C13: 108694 | D13: 109573 | E13: 113441 | F13: 112439 | G13: 113453 | H13: =(I13+G13)/2 -> 112080 | I13: 110707 | J13: 111010 | K13: =(L13+J13)/2 -> 114186.5 | L13: 117363 | M13: 118092 | N13: 128026 | O13: 129242 | P13: 130419 | Q13: 131560 | R13: 132667 | S13: 127907 | T13: 128969 | U13: 130009 | V13: 131026
... A225: 1504703 | B225: Moju (PA) | C225: 55583 | D225: 56810 | E225: 59592 | F225: 60809 | G225: 62223 | H225: =(I225+G225)/2 -> 64709 | I225: 67195 | J225: 68600 | K225: =(L225+J225)/2 -> 69964.5 | L225: 71329 | M225: 72597 | N225: 74768 | O225: 76096 | P225: 77385 | Q225: 78629 | R225: 79825 | S225: 80988 | T225: 82094 | U225: 83182 | V225: 84251
A226: 1504752 | B226: Mojuí dos Campos (PA) | C226: ... | D226: ... | E226: ... | F226: ... | G226: ... | H226: =(I226+G226)/2 -> #VALUE! | I226: ... | J226: ... | K226: =(L226+J226)/2 -> #VALUE! | L226: ... | M226: 15018 | N226: 15232 | O226: 15341 | P226: 15446 | Q226: 15548 | R226: 15646 | S226: 15982 | T226: 16084 | U226: 16184 | V226: 16282
A227: 1504802 | B227: Monte Alegre (PA) | C227: 62041 | D227: 63396 | E227: 66467 | F227: 67811 | G227: 69372 | H227: =(I227+G227)/2 -> 66457.5 | I227: 63543 | J227: 63941 | K227: =(L227+J227)/2 -> 59788.5 | L227: 55636 | M227: 55804 | N227: 56147 | O227: 56231 | P227: 56312 | Q227: 56391 | R227: 56466 | S227: 57900 | T227: 58032 | U227: 58162 | V227: 58289
A228: 1504901 | B228: Muaná (PA) | C228: 26119 | D228: 26422 | E228: 27109 | F228: 27409 | G228: 27758 | H228: =(I228+G228)/2 -> 28937.5 | I228: 30117 | J228: 30568 | K228: =(L228+J228)/2 -> 32721.5 | L228: 34875 | M228: 35524 | N228: 36632 | O228: 37314 | P228: 37977 | Q228: 38616 | R228: 39231 | S228: 39783 | T228: 40349 | U228: 40906 | V228: 41454
A229: 1504950 | B229: Nova Esperança do Piriá (PA) | C229: 21469 | D229: 22665 | E229: 25377 | F229: 26564 | G229: 27943 | H229: =(I229+G229)/2 -> 25771 | I229: 23599 | J229: 24062 | K229: =(L229+J229)/2 -> 22159 | L229: 20256 | M229: 20350 | N229: 20528 | O229: 20596 | P229: 20663 | Q229: 20727 | R229: 20789 | S229: 21291 | T229: 21368 | U229: 21444 | V229: 21519
A230: 1504976 | B230: Nova Ipixuna (PA) | C230: 12573 | D230: 12900 | E230: 13644 | F230: 13970 | G230: 14348 | H230: =(I230+G230)/2 -> 14578 | I230: 14808 | J230: 15097 | K230: =(L230+J230)/2 -> 14978 | L230: 14859 | M230: 15065 | N230: 15422 | O230: 15632 | P230: 15836 | Q230: 16032 | R230: 16221 | S230: 16499 | T230: 16678 | U230: 16854 | V230: 17027
A231: 1505007 | B231: Nova Timboteua (PA) | C231: 11822 | D231: 12016 | E231: 12454 | F231: 12646 | G231: 12869 | H231: =(I231+G231)/2 -> 12718.5 | I231: 12568 | J231: 12677 | K231: =(L231+J231)/2 -> 13260.5 | L231: 13844 | M231: 14012 | N231: 14305 | O231: 14472 | P231: 14635 | Q231: 14791 | R231: 14942 | S231: 15218 | T231: 15363 | U231: 15506 | V231: 15646
A232: 1505031 | B232: Novo Progresso (PA) | C232: 29018 | D232: 30907 | E232: 35192 | F232: 37067 | G232: 39245 | H232: =(I232+G232)/2 -> 30544 | I232: 21843 | J232: 21504 | K232: =(L232+J232)/2 -> 23321 | L232: 25138 | M232: 25151 | N232: 25203 | O232: 25169 | P232: 25135 | Q232: 25102 | R232: 25071 | S232: 25758 | T232: 25762 | U232: 25766 | V232: 25769
A233: 1505064 | B233: Novo Repartimento (PA) | C233: 44610 | D233: 45906 | E233: 48846 | F233: 50133 | G233: 51627 | H233: =(I233+G233)/2 -> 53066.5 | I233: 54506 | J233: 55762 | K233: =(L233+J233)/2 -> 59683 | L233: 63604 | M233: 65106 | N233: 67652 | O233: 69267 | P233: 70835 | Q233: 72347 | R233: 73802 | S233: 74602 | T233: 75919 | U233: 77214 | V233: 78488
A234: 1505106 | B234: Óbidos (PA) | C234: 47370 | D234: 47779 | E234: 48705 | F234: 49111 | G234: 49582 | H234: =(I234+G234)/2 -> 48934.5 | I234: 48287 | J234: 48429 | K234: =(L234+J234)/2 -> 48990.5 | L234: 49552 | M234: 49763 | N234: 50171 | O234: 50317 | P234: 50459 | Q234: 50596 | R234: 50727 | S234: 51964 | T234: 52137 | U234: 52306 | V234: 52473
A235: 1505205 | B235: Oeiras do Pará (PA) | C235: 24194 | D235: 24630 | E235: 25619 | F235: 26051 | G235: 26554 | H235: =(I235+G235)/2 -> 26520.5 | I235: 26487 | J235: 26796 | K235: =(L235+J235)/2 -> 27900.5 | L235: 29005 | M235: 29402 | N235: 30088 | O235: 30490 | P235: 30880 | Q235: 31257 | R235: 31619 | S235: 32168 | T235: 32512 | U235: 32850 | V235: 33182
A236: 1505304 | B236: Oriximiná (PA) | C236: 49945 | D236: 50694 | E236: 52392 | F236: 53135 | G236: 53999 | H236: =(I236+G236)/2 -> 55882 | I236: 57765 | J236: 58683 | K236: =(L236+J236)/2 -> 61294 | L236: 63905 | M236: 64978 | N236: 66821 | O236: 67939 | P236: 69024 | Q236: 70071 | R236: 71078 | S236: 72160 | T236: 73096 | U236: 74016 | V236: 74921
A237: 1505403 | B237: Ourém (PA) | C237: 14741 | D237: 14900 | E237: 15262 | F237: 15421 | G237: 15605 | H237: =(I237+G237)/2 -> 15662 | I237: 15719 | J237: 15841 | K237: =(L237+J237)/2 -> 16149.5 | L237: 16458 | M237: 16601 | N237: 16854 | O237: 16986 | P237: 17114 | Q237: 17237 | R237: 17356 | S237: 17721 | T237: 17842 | U237: 17961 | V237: 18079
A238: 1505437 | B238: Ourilândia do Norte (PA) | C238: 19637 | D238: 19714 | E238: 19889 | F238: 19965 | G238: 20054 | H238: =(I238+G238)/2 -> 20612.5 | I238: 21171 | J238: 21327 | K238: =(L238+J238)/2 -> 24646 | L238: 27965 | M238: 28551 | N238: 29547 | O238: 30171 | P238: 30776 | Q238: 31359 | R238: 31921 | S238: 32319 | T238: 32832 | U238: 33335 | V238: 33831
... A681: 2200905 | B681: Aroazes (PI) | C681: 6065 | D681: 6083 | E681: 6122 | F681: 6143 | G681: 6165 | H681: =(I681+G681)/2 -> 6095 | I681: 6025 | J681: 6019 | K681: =(L681+J681)/2 -> 5890 | L681: 5761 | M681: 5742 | N681: 5784 | O681: 5773 | P681: 5763 | Q681: 5755 | R681: 5748 | S681: 5844 | T681: 5835 | U681: 5827 | V681: 5819
A682: 2200954 | B682: Aroeiras do Itaim (PI) | C682: ... | D682: ... | E682: 2561 | F682: 2591 | G682: 2620 | H682: =(I682+G682)/2 -> 2675.5 | I682: 2731 | J682: 2759 | K682: =(L682+J682)/2 -> 2600 | L682: 2441 | M682: 2442 | N682: 2459 | O682: 2460 | P682: 2460 | Q682: 2460 | R682: 2511 | S682: 2551 | T682: 2551 | U682: 2551 | V682: 2551
A683: 2201002 | B683: Arraial (PI) | C683: 4848 | D683: 4820 | E683: 4760 | F683: 4727 | G683: 4695 | H683: =(I683+G683)/2 -> 4920 | I683: 5145 | J683: 5165 | K683: =(L683+J683)/2 -> 4918.5 | L683: 4672 | M683: 4655 | N683: 4688 | O683: 4678 | P683: 4670 | Q683: 4662 | R683: 4656 | S683: 4735 | T683: 4727 | U683: 4720 | V683: 4713
A684: 2201051 | B684: Assunção do Piauí (PI) | C684: 7085 | D684: 7155 | E684: 7303 | F684: 7385 | G684: 7467 | H684: =(I684+G684)/2 -> 7855 | I684: 8243 | J684: 8370 | K684: =(L684+J684)/2 -> 7958.5 | L684: 7547 | M684: 7590 | N684: 7645 | O684: 7667 | P684: 7686 | Q684: 7703 | R684: 7717 | S684: 7828 | T684: 7846 | U684: 7863 | V684: 7879
A685: 2201101 | B685: Avelino Lopes (PI) | C685: 9853 | D685: 9959 | E685: 10373 | F685: 10497 | G685: 10620 | H685: =(I685+G685)/2 -> 11230 | I685: 11840 | J685: 12039 | K685: =(L685+J685)/2 -> 11601.5 | L685: 11164 | M685: 11258 | N685: 11341 | O685: 11390 | P685: 11433 | Q685: 11471 | R685: 11503 | S685: 11252 | T685: 11289 | U685: 11326 | V685: 11361
A686: 2201150 | B686: Baixa Grande do Ribeiro (PI) | C686: 8118 | D686: 8275 | E686: 8605 | F686: 8787 | G686: 8968 | H686: =(I686+G686)/2 -> 9749.5 | I686: 10531 | J686: 10804 | K686: =(L686+J686)/2 -> 10765.5 | L686: 10727 | M686: 10930 | N686: 11014 | O686: 11123 | P686: 11218 | Q686: 11302 | R686: 11375 | S686: 11497 | T686: 11586 | U686: 11671 | V686: 11751
A687: 2201176 | B687: Barra D'Alcântara (PI) | C687: 4048 | D687: 4021 | E687: 3679 | F687: 3650 | G687: 3621 | H687: =(I687+G687)/2 -> 3751.5 | I687: 3882 | J687: 3886 | K687: =(L687+J687)/2 -> 3870.5 | L687: 3855 | M687: 3858 | N687: 3886 | O687: 3886 | P687: 3887 | Q687: 3888 | R687: 3889 | S687: 3950 | T687: 3951 | U687: 3952 | V687: 3953
A688: 2201200 | B688: Barras (PI) | C688: 41464 | D688: 41730 | E688: 42288 | F688: 42596 | G688: 42903 | H688: =(I688+G688)/2 -> 43738.5 | I688: 44574 | J688: 44913 | K688: =(L688+J688)/2 -> 45033.5 | L688: 45154 | M688: 45448 | N688: 45786 | O688: 45938 | P688: 46072 | Q688: 46189 | R688: 46291 | S688: 46941 | T688: 47066 | U688: 47185 | V688: 47298
A689: 2201309 | B689: Barreiras do Piauí (PI) | C689: 3144 | D689: 3165 | E689: 3210 | F689: 3235 | G689: 3259 | H689: =(I689+G689)/2 -> 3355.5 | I689: 3452 | J689: 3485 | K689: =(L689+J689)/2 -> 3365 | L689: 3245 | M689: 3255 | N689: 3278 | O689: 3283 | P689: 3287 | Q689: 3291 | R689: 3294 | S689: 3344 | T689: 3348 | U689: 3352 | V689: 3356
A690: 2201408 | B690: Barro Duro (PI) | C690: 6941 | D690: 7012 | E690: 7162 | F690: 7244 | G690: 7327 | H690: =(I690+G690)/2 -> 7089.5 | I690: 6852 | J690: 6853 | K690: =(L690+J690)/2 -> 6723.5 | L690: 6594 | M690: 6580 | N690: 6627 | O690: 6941 | P690: 6935 | Q690: 6930 | R690: 6925 | S690: 7038 | T690: 7032 | U690: 7027 | V690: 7022
A691: 2201507 | B691: Batalha (PI) | C691: 24813 | D691: 25131 | E691: 25800 | F691: 26169 | G691: 26536 | H691: =(I691+G691)/2 -> 26500.5 | I691: 26465 | J691: 26681 | K691: =(L691+J691)/2 -> 26291 | L691: 25901 | M691: 26023 | N691: 26215 | O691: 26277 | P691: 26331 | Q691: 26379 | R691: 26421 | S691: 26806 | T691: 26857 | U691: 26905 | V691: 26951
A692: 2201556 | B692: Bela Vista do Piauí (PI) | C692: 2935 | D692: 2923 | E692: 2896 | F692: 2881 | G692: 2866 | H692: =(I692+G692)/2 -> 3295.5 | I692: 3725 | J692: 3762 | K692: =(L692+J692)/2 -> 3789.5 | L692: 3817 | M692: 3854 | N692: 3882 | O692: 3902 | P692: 3919 | Q692: 3934 | R692: 3947 | S692: 3999 | T692: 4015 | U692: 4030 | V692: 4044
A693: 2201572 | B693: Belém do Piauí (PI) | C693: 2447 | D693: 2455 | E693: 2473 | F693: 2482 | G693: 2492 | H693: =(I693+G693)/2 -> 2680.5 | I693: 2869 | J693: 2912 | K693: =(L693+J693)/2 -> 3124.5 | L693: 3337 | M693: 3388 | N693: 3413 | O693: 3440 | P693: 3464 | Q693: 3485 | R693: 3503 | S693: 3544 | T693: 3566 | U693: 3587 | V693: 3607
...

Sheet Tabela_2
A1: Cód. | B1: Município | C1: 2003 | D1: 2004 | E1: 2005 | F1: 2006 | G1: 2007 | H1: 2008 | I1: 2009 | J1: 2010 | K1: 2011 | L1: 2012 | M1: 2013 | N1: 2014 | O1: 2015 | P1: 2016 | Q1: 2017 | R1: 2018 | S1: 2019 | T1: 2020 | U1: 2021
A2: 1100015 | B2: Alta Floresta D'Oeste (RO) | C2: =(Tabela!D2-Tabela!C2)/Tabela!C2 -> 0.011969013 | D2: =(Tabela!E2-Tabela!D2)/Tabela!D2 -> 0.052171389 | E2: =(Tabela!F2-Tabela!E2)/Tabela!E2 -> -0.012827144 | F2: =(Tabela!G2-Tabela!F2)/Tabela!F2 -> 0.013133536 | G2: =(Tabela!H2-Tabela!G2)/Tabela!G2 -> -0.076331667 | H2: =(Tabela!I2-Tabela!H2)/Tabela!H2 -> -0.082639692 | I2: =(Tabela!J2-Tabela!I2)/Tabela!I2 -> -0.009073524 | J2: =(Tabela!K2-Tabela!J2)/Tabela!J2 -> -0.0025868441 | ... U2: =(Tabela!V2-Tabela!U2)/Tabela!U2 -> -0.0093277015
A3: 1100023 | B3: Ariquemes (RO) | C3: =(Tabela!D3-Tabela!C3)/Tabela!C3 -> 0.021027948 | D3: =(Tabela!E3-Tabela!D3)/Tabela!D3 -> 0.090625 | E3: =(Tabela!F3-Tabela!E3)/Tabela!E3 -> -0.02151874 | F3: =(Tabela!G3-Tabela!F3)/Tabela!F3 -> 0.022262469 | G3: =(Tabela!H3-Tabela!G3)/Tabela!G3 -> -0.013477291 | H3: =(Tabela!I3-Tabela!H3)/Tabela!H3 -> -0.013661409 | I3: =(Tabela!J3-Tabela!I3)/Tabela!I3 -> 0.011350067 | J3: =(Tabela!K3-Tabela!J3)/Tabela!J3 -> 0.035240411 | ... U3: =(Tabela!V3-Tabela!U3)/Tabela!U3 -> 0.014837066
A4: 1100031 | B4: Cabixi (RO) | C4: =(Tabela!D4-Tabela!C4)/Tabela!C4 -> -0.0016021362 | D4: =(Tabela!E4-Tabela!D4)/Tabela!D4 -> -0.0076223589 | E4: =(Tabela!F4-Tabela!E4)/Tabela!E4 -> 0.0020212909 | F4: =(Tabela!G4-Tabela!F4)/Tabela!F4 -> -0.0020172136 | G4: =(Tabela!H4-Tabela!G4)/Tabela!G4 -> -0.043390379 | H4: =(Tabela!I4-Tabela!H4)/Tabela!H4 -> -0.045358501 | I4: =(Tabela!J4-Tabela!I4)/Tabela!I4 -> -0.012099749 | J4: =(Tabela!K4-Tabela!J4)/Tabela!J4 -> -0.035399552 | ... U4: =(Tabela!V4-Tabela!U4)/Tabela!U4 -> -0.023323053
A5: 1100049 | B5: Cacoal (RO) | C5: =(Tabela!D5-Tabela!C5)/Tabela!C5 -> 0.0050684987 | D5: =(Tabela!E5-Tabela!D5)/Tabela!D5 -> 0.022191605 | E5: =(Tabela!F5-Tabela!E5)/Tabela!E5 -> -0.0056139341 | F5: =(Tabela!G5-Tabela!F5)/Tabela!F5 -> 0.0057114281 | G5: =(Tabela!H5-Tabela!G5)/Tabela!G5 -> 0.012044961 | H5: =(Tabela!I5-Tabela!H5)/Tabela!H5 -> 0.011901606 | I5: =(Tabela!J5-Tabela!I5)/Tabela!I5 -> 0.0052643011 | J5: =(Tabela!K5-Tabela!J5)/Tabela!J5 -> 0.0018048935 | ... U5: =(Tabela!V5-Tabela!U5)/Tabela!U5 -> 0.0060889712
A6: 1100056 | B6: Cerejeiras (RO) | C6: =(Tabela!D6-Tabela!C6)/Tabela!C6 -> -0.0073082287 | D6: =(Tabela!E6-Tabela!D6)/Tabela!D6 -> -0.032426661 | E6: =(Tabela!F6-Tabela!E6)/Tabela!E6 -> 0.0086542371 | F6: =(Tabela!G6-Tabela!F6)/Tabela!F6 -> -0.0086951514 | G6: =(Tabela!H6-Tabela!G6)/Tabela!G6 -> -0.012518153 | H6: =(Tabela!I6-Tabela!H6)/Tabela!H6 -> -0.012676843 | I6: =(Tabela!J6-Tabela!I6)/Tabela!I6 -> -0.0096520496 | J6: =(Tabela!K6-Tabela!J6)/Tabela!J6 -> 0.0095355553 | ... U6: =(Tabela!V6-Tabela!U6)/Tabela!U6 -> -0.0071587262
A7: 1100064 | B7: Colorado do Oeste (RO) | C7: =(Tabela!D7-Tabela!C7)/Tabela!C7 -> -0.02246061 | D7: =(Tabela!E7-Tabela!D7)/Tabela!D7 -> -0.101068 | E7: =(Tabela!F7-Tabela!E7)/Tabela!E7 -> 0.029102403 | F7: =(Tabela!G7-Tabela!F7)/Tabela!F7 -> -0.028650109 | G7: =(Tabela!H7-Tabela!G7)/Tabela!G7 -> -0.0034347399 | H7: =(Tabela!I7-Tabela!H7)/Tabela!H7 -> -0.003446578 | I7: =(Tabela!J7-Tabela!I7)/Tabela!I7 -> -0.021629337 | J7: =(Tabela!K7-Tabela!J7)/Tabela!J7 -> 0.01447649 | ... U7: =(Tabela!V7-Tabela!U7)/Tabela!U7 -> -0.02129439
A8: 1100072 | B8: Corumbiara (RO) | C8: =(Tabela!D8-Tabela!C8)/Tabela!C8 -> -0.013582677 | D8: =(Tabela!E8-Tabela!D8)/Tabela!D8 -> -0.060965875 | E8: =(Tabela!F8-Tabela!E8)/Tabela!E8 -> 0.016788864 | F8: =(Tabela!G8-Tabela!F8)/Tabela!F8 -> -0.01672066 | G8: =(Tabela!H8-Tabela!G8)/Tabela!G8 -> 0.018705495 | H8: =(Tabela!I8-Tabela!H8)/Tabela!H8 -> 0.018362024 | I8: =(Tabela!J8-Tabela!I8)/Tabela!I8 -> -0.0082983301 | J8: =(Tabela!K8-Tabela!J8)/Tabela!J8 -> -0.052944215 | ... U8: =(Tabela!V8-Tabela!U8)/Tabela!U8 -> -0.023268698
A9: 1100080 | B9: Costa Marques (RO) | C9: =(Tabela!D9-Tabela!C9)/Tabela!C9 -> 0.033874382 | D9: =(Tabela!E9-Tabela!D9)/Tabela!D9 -> 0.14392979 | E9: =(Tabela!F9-Tabela!E9)/Tabela!E9 -> -0.032563294 | F9: =(Tabela!G9-Tabela!F9)/Tabela!F9 -> 0.034011807 | G9: =(Tabela!H9-Tabela!G9)/Tabela!G9 -> 0.095355773 | H9: =(Tabela!I9-Tabela!H9)/Tabela!H9 -> 0.087054613 | I9: =(Tabela!J9-Tabela!I9)/Tabela!I9 -> 0.034280398 | J9: =(Tabela!K9-Tabela!J9)/Tabela!J9 -> -0.014842236 | ... U9: =(Tabela!V9-Tabela!U9)/Tabela!U9 -> 0.024311097
A10: 1100098 | B10: Espigão D'Oeste (RO) | C10: =(Tabela!D10-Tabela!C10)/Tabela!C10 -> 0.0094199306 | D10: =(Tabela!E10-Tabela!D10)/Tabela!D10 -> 0.041106241 | E10: =(Tabela!F10-Tabela!E10)/Tabela!E10 -> -0.010233706 | F10: =(Tabela!G10-Tabela!F10)/Tabela!F10 -> 0.010449512 | G10: =(Tabela!H10-Tabela!G10)/Tabela!G10 -> 0.019195181 | H10: =(Tabela!I10-Tabela!H10)/Tabela!H10 -> 0.018833666 | I10: =(Tabela!J10-Tabela!I10)/Tabela!I10 -> 0.0096096726 | J10: =(Tabela!K10-Tabela!J10)/Tabela!J10 -> 0.0012287138 | ... U10: =(Tabela!V10-Tabela!U10)/Tabela!U10 -> 0.009603915
A11: 1100106 | B11: Guajará-Mirim (RO) | C11: =(Tabela!D11-Tabela!C11)/Tabela!C11 -> 0.013624534 | D11: =(Tabela!E11-Tabela!D11)/Tabela!D11 -> 0.059076722 | E11: =(Tabela!F11-Tabela!E11)/Tabela!E11 -> -0.014450386 | F11: =(Tabela!G11-Tabela!F11)/Tabela!F11 -> 0.01483107 | G11: =(Tabela!H11-Tabela!G11)/Tabela!G11 -> -0.018309491 | H11: =(Tabela!I11-Tabela!H11)/Tabela!H11 -> -0.018650981 | I11: =(Tabela!J11-Tabela!I11)/Tabela!I11 -> 0.0054512716 | J11: =(Tabela!K11-Tabela!J11)/Tabela!J11 -> 0.014376135 | ... U11: =(Tabela!V11-Tabela!U11)/Tabela!U11 -> 0.0080333362
A12: 1100114 | B12: Jaru (RO) | C12: =(Tabela!D12-Tabela!C12)/Tabela!C12 -> 0.0064211069 | D12: =(Tabela!E12-Tabela!D12)/Tabela!D12 -> 0.028098207 | E12: =(Tabela!F12-Tabela!E12)/Tabela!E12 -> -0.0070770653 | F12: =(Tabela!G12-Tabela!F12)/Tabela!F12 -> 0.0071991404 | G12: =(Tabela!H12-Tabela!G12)/Tabela!G12 -> -0.020331781 | H12: =(Tabela!I12-Tabela!H12)/Tabela!H12 -> -0.020753741 | I12: =(Tabela!J12-Tabela!I12)/Tabela!I12 -> -0.00022240756 | J12: =(Tabela!K12-Tabela!J12)/Tabela!J12 -> -0.019094229 | ... U12: =(Tabela!V12-Tabela!U12)/Tabela!U12 -> -0.0029252228
A13: 1100122 | B13: Ji-Paraná (RO) | C13: =(Tabela!D13-Tabela!C13)/Tabela!C13 -> 0.0080869229 | D13: =(Tabela!E13-Tabela!D13)/Tabela!D13 -> 0.035300667 | E13: =(Tabela!F13-Tabela!E13)/Tabela!E13 -> -0.0088327853 | F13: =(Tabela!G13-Tabela!F13)/Tabela!F13 -> 0.0090182232 | G13: =(Tabela!H13-Tabela!G13)/Tabela!G13 -> -0.012101928 | H13: =(Tabela!I13-Tabela!H13)/Tabela!H13 -> -0.012250178 | I13: =(Tabela!J13-Tabela!I13)/Tabela!I13 -> 0.0027369543 | J13: =(Tabela!K13-Tabela!J13)/Tabela!J13 -> 0.028614539 | ... U13: =(Tabela!V13-Tabela!U13)/Tabela!U13 -> 0.0078225354
... A5571: 5300108 | B5571: Brasília (DF) | C5571: =(Tabela!D5571-Tabela!C5571)/Tabela!C5571 -> 0.020481499 | D5571: =(Tabela!E5571-Tabela!D5571)/Tabela!D5571 -> 0.042131913 | E5571: =(Tabela!F5571-Tabela!E5571)/Tabela!E5571 -> 0.022374191 | F5571: =(Tabela!G5571-Tabela!F5571)/Tabela!F5571 -> 0.021720383 | G5571: =(Tabela!H5571-Tabela!G5571)/Tabela!G5571 -> 0.036365501 | H5571: =(Tabela!I5571-Tabela!H5571)/Tabela!H5571 -> 0.035089456 | I5571: =(Tabela!J5571-Tabela!I5571)/Tabela!I5571 -> 0.019445799 | J5571: =(Tabela!K5571-Tabela!J5571)/Tabela!J5571 -> 0.00059707275 | ... U5571: =(Tabela!V5571-Tabela!U5571)/Tabela!U5571 -> 0.012822943
A5572: Fonte: IBGE - Estimativas de População

Sheet Notas
A1: Notas
A2: Em 2003: O contingente populacional estimado para o Município de Caraíbas, no Estado da Bahia foi reduzido em 5.006 habitantes, devido ao processo de sindicância recentemente encerrado que apurou sobre enumeração ocorrida quando da realização do Censo Demográfico 2000. Em 2004:
A3: 1 - O contingente populacional estimado para o Município de Caraíbas, no Estado da Bahia foi reduzido em 5.006 habitantes, devido ao processo de sindicância recentemente encerrado que apurou sobre enumeração ocorrida quando da realização do Censo Demográfico 2000.
A4: 2 - Inclusive 4 municípios com instalação prevista para 1º de janeiro de 2005: Aroeiras do Itaim (PI), Figueirão (MS), Ipiranga do Norte (MT) e Itanhangá (MT). Em 2008: Inclusive o Município de Nazária - PI, com previsão de instalação em 1º de janeiro de 2009. Em 2009: Por determinação judicial e para efeito de distribuição do Fundo de Participação dos Municípios, a população do Município de Uruará-PA é de 59.881 habitantes. Processo Judicial nº 2008.39.03.000085-6. Em 2011:
A5: 1 - A população do Brasil difere em 2.791 pessoas (192.379.287 pessoas) em relação àquela divulgada no D.O.U em 31/08/2011 (192.376.496 pessoas) em decorrência do critério de arredondamento para números inteiros, a ser adotado a partir deste ano.
A6: 2 - O Município de Santarém-PB, código 13653, passou a ser denominado oficialmente de Joca Claudino-PB a partir de 23/11/2010, por força de Lei Municipal nº 049/2010.
A7: 3 - o Município de Campo de Santana-PB, código 16409, passou a ser denominado oficialmente de Tacima-PB a partir de 30/12/2009, por força de Lei Complementar nº 016/2009. Em 2012:
A8: 1 - Por determinação judicial e para efeito de distribuição do Fundo de Participação dos Municípios, a população do Município de Brasil Novo-PA é de 17.960 habitantes. Processo Judicial nº 1-28.2012.4.01.3903.
A9: 2 - Por determinação judicial e para efeito de distribuição do Fundo de Participação dos Municípios, a população do Município de Jacareacanga-PA é de 41.487 habitantes. Processo Judicial nº 798-41.2011.4.01.3902, Seção Judiciária de Itaituba-PA.
A10: 3 - Municípios instalados em 1º de janeiro de 2013. Em 2013: Por determinação judicial e para efeito de distribuição do Fundo de Participação dos Municípios, a população do Município de Jacareacanga-PA é de 41.487 habitantes. Processo Judicial nº 798-41.2011 4.01.3902 Seção Judiciária de Itaituba-PA. Em 2014:
A11: 1 - Por determinação judicial e para efeito de distribuição do Fundo de Participação dos Municípios, a população do Município de Jacareacanga-PA é de 41.487 habitantes. Processo Judicial nº 798-41.2011.4.01.3902, Seção Judiciária de Itaituba-PA.
A12: 2 - Por determinação judicial o Município de Coronel João Sá - BA teve os efeitos das estimativas das populações de 2014, 2015 e 2016 suspensas, passando a vigorar, para efeito de distribuição do Fundo de Participação dos Municípios, a população estimada para o ano de 2013, que foi de 17.422 habitantes. Processo Judicial nº 0002222-53.2017.4.01.3306 - Vara Única de Paulo Afonso-BA. Em 2015:
... A142: Legenda
A143: Símbolo | B143: Significado
A144: - | B144: Zero absoluto, não resultante de um cálculo ou arredondamento. Ex: Em determinado município não existem pessoas de 14 anos de idade sem instrução.
A145: 0 | B145: Zero resultante de um cálculo ou arredondamento. Ex: A inflação do feijão em determinada Região Metropolitana foi 0. Determinado município produziu 400 kg de sementes de girassol e os dados da tabela são expressos em toneladas.
A146: X | B146: Valor inibido para não identificar o informante. Ex: Determinado município só possui uma empresa produtora de cimento, logo o valor de sua produção deve ser inibido.
A147: .. | B147: Valor não se aplica. Ex: Não se pode obter o total da produção agrícola em determinado município quando os produtos agrícolas são contabilizados com unidades de medida distintas.
A148: ... | B148: Valor não disponível. Ex: A produção de feijão em determinado município não foi pesquisada ou determinado município não existia no ano da pesquisa.
A149: A a Z (exceto X) | B149: Significa uma faixa de valores. Varia em função da tabela (se for o caso). Ex: O nível de precisão da produção estimada de combustíveis está na faixa A (95 a 100%)
